Workbook

Sheet Dashboard
B1: VIDEO GAME INDUSTRY DASHBOARD
B3: Global sales in millions of units | 1980-2016 | Source: Video_Games_Sales_as_at_22_Dec_2016 (cleaned)
B4: GENRE | D4: PLATFORM MAKER | F4: YEAR FROM | H4: YEAR TO | J4: Pick values in the yellow cells (dropdowns). Every KPI and chart updates. Set all back to "All" / 1980-2016 to reset.
B5: All | D5: All | F5: 1980 | H5: 2016
B7: TOTAL RELEASES | D7: TOTAL SALES (M UNITS) | F7: TOP GENRE | H7: TOP PLATFORM | J7: TOP PUBLISHER | L7: AVG SALES / RELEASE (M)
B8: =SUM(Data!$P$2:$P$16716) -> 16715 | D8: =SUMIFS(Data!$J$2:$J$16716,Data!$P$2:$P$16716,1) -> 8917.88 | F8: =IF(SUM(Calc!$C$3:$C$14)=0,"n/a",INDEX(Calc!$A$3:$A$14,MATCH(MAX(Calc!$C$3:$C$14),Calc!$C$3:$C$14,0))) -> Action | H8: =IF(Calc!$V$3=0,"n/a",Calc!$U$3) -> PS2 | J8: =IF(Calc!$AD$3=0,"n/a",Calc!$AC$3) -> Nintendo | L8: =IF(B8=0,0,D8/B8) -> 0.53352558
B9: ="game releases (title x platform)" -> game releases (title x platform) | D9: =IFERROR(TEXT(D8/SUM(Data!$J$2:$J$16716),"0.0%")&" of all-time market","") -> 100.0% of all-time market | F9: =IFERROR(TEXT(MAX(Calc!$C$3:$C$14)/D8,"0.0%")&" of selected sales","") -> 19.6% of selected sales | H9: =IFERROR(TEXT(Calc!$V$3/D8,"0.0%")&" of selected sales","") -> 14.1% of selected sales | J9: =IFERROR(TEXT(Calc!$AD$3/D8,"0.0%")&" of selected sales","") -> 20.1% of selected sales | L9: ="mean units per release" -> mean units per release
B65: Note: critic-band chart covers only games that have a Metacritic score (~49%). Digital/mobile sales are not included in the source data; 2016 is a partial year.

Sheet Data
A1: Name | B1: Platform | C1: Year | D1: Genre | E1: Publisher | F1: NA_Sales | G1: EU_Sales | H1: JP_Sales | I1: Other_Sales | J1: Global_Sales | K1: Critic_Score | L1: User_Score | M1: Rating | N1: Platform_Maker | O1: Critic_Band | P1: InFilter | Q1: RankVal
A2: Wii Sports | B2: Wii | C2: 2006 | D2: Sports | E2: Nintendo | F2: 41.36 | G2: 28.96 | H2: 3.77 | I2: 8.45 | J2: 82.53 | K2: 76 | L2: 8 | M2: E | N2: Nintendo | O2: 70-79 | P2: =IF(AND(OR(Dashboard!$B$5="All",D2=Dashboard!$B$5),OR(Dashboard!$D$5="All",N2=Dashboard!$D$5),OR(AND(C2<>"",C2>=Dashboard!$F$5,C2<=Dashboard!$H$5),AND(C2="",Dashboard!$F$5<=1980,Dashboard!$H$5>=2016))),1,0) -> 1 | Q2: =J2*P2+ROW()*0.00000001 -> 82.53
A3: Super Mario Bros. | B3: NES | C3: 1985 | D3: Platform | E3: Nintendo | F3: 29.08 | G3: 3.58 | H3: 6.81 | I3: 0.77 | J3: 40.24 | N3: Nintendo | P3: =IF(AND(OR(Dashboard!$B$5="All",D3=Dashboard!$B$5),OR(Dashboard!$D$5="All",N3=Dashboard!$D$5),OR(AND(C3<>"",C3>=Dashboard!$F$5,C3<=Dashboard!$H$5),AND(C3="",Dashboard!$F$5<=1980,Dashboard!$H$5>=2016))),1,0) -> 1 | Q3: =J3*P3+ROW()*0.00000001 -> 40.24
A4: Mario Kart Wii | B4: Wii | C4: 2008 | D4: Racing | E4: Nintendo | F4: 15.68 | G4: 12.76 | H4: 3.79 | I4: 3.29 | J4: 35.52 | K4: 82 | L4: 8.3 | M4: E | N4: Nintendo | O4: 80-89 | P4: =IF(AND(OR(Dashboard!$B$5="All",D4=Dashboard!$B$5),OR(Dashboard!$D$5="All",N4=Dashboard!$D$5),OR(AND(C4<>"",C4>=Dashboard!$F$5,C4<=Dashboard!$H$5),AND(C4="",Dashboard!$F$5<=1980,Dashboard!$H$5>=2016))),1,0) -> 1 | Q4: =J4*P4+ROW()*0.00000001 -> 35.52
A5: Wii Sports Resort | B5: Wii | C5: 2009 | D5: Sports | E5: Nintendo | F5: 15.61 | G5: 10.93 | H5: 3.28 | I5: 2.95 | J5: 32.77 | K5: 80 | L5: 8 | M5: E | N5: Nintendo | O5: 70-79 | P5: =IF(AND(OR(Dashboard!$B$5="All",D5=Dashboard!$B$5),OR(Dashboard!$D$5="All",N5=Dashboard!$D$5),OR(AND(C5<>"",C5>=Dashboard!$F$5,C5<=Dashboard!$H$5),AND(C5="",Dashboard!$F$5<=1980,Dashboard!$H$5>=2016))),1,0) -> 1 | Q5: =J5*P5+ROW()*0.00000001 -> 32.77
A6: Pokemon Red/Pokemon Blue | B6: GB | C6: 1996 | D6: Role-Playing | E6: Nintendo | F6: 11.27 | G6: 8.89 | H6: 10.22 | I6: 1 | J6: 31.37 | N6: Nintendo | P6: =IF(AND(OR(Dashboard!$B$5="All",D6=Dashboard!$B$5),OR(Dashboard!$D$5="All",N6=Dashboard!$D$5),OR(AND(C6<>"",C6>=Dashboard!$F$5,C6<=Dashboard!$H$5),AND(C6="",Dashboard!$F$5<=1980,Dashboard!$H$5>=2016))),1,0) -> 1 | Q6: =J6*P6+ROW()*0.00000001 -> 31.37
A7: Tetris | B7: GB | C7: 1989 | D7: Puzzle | E7: Nintendo | F7: 23.2 | G7: 2.26 | H7: 4.22 | I7: 0.58 | J7: 30.26 | N7: Nintendo | P7: =IF(AND(OR(Dashboard!$B$5="All",D7=Dashboard!$B$5),OR(Dashboard!$D$5="All",N7=Dashboard!$D$5),OR(AND(C7<>"",C7>=Dashboard!$F$5,C7<=Dashboard!$H$5),AND(C7="",Dashboard!$F$5<=1980,Dashboard!$H$5>=2016))),1,0) -> 1 | Q7: =J7*P7+ROW()*0.00000001 -> 30.26
A8: New Super Mario Bros. | B8: DS | C8: 2006 | D8: Platform | E8: Nintendo | F8: 11.28 | G8: 9.14 | H8: 6.5 | I8: 2.88 | J8: 29.8 | K8: 89 | L8: 8.5 | M8: E | N8: Nintendo | O8: 80-89 | P8: =IF(AND(OR(Dashboard!$B$5="All",D8=Dashboard!$B$5),OR(Dashboard!$D$5="All",N8=Dashboard!$D$5),OR(AND(C8<>"",C8>=Dashboard!$F$5,C8<=Dashboard!$H$5),AND(C8="",Dashboard!$F$5<=1980,Dashboard!$H$5>=2016))),1,0) -> 1 | Q8: =J8*P8+ROW()*0.00000001 -> 29.8
A9: Wii Play | B9: Wii | C9: 2006 | D9: Misc | E9: Nintendo | F9: 13.96 | G9: 9.18 | H9: 2.93 | I9: 2.84 | J9: 28.92 | K9: 58 | L9: 6.6 | M9: E | N9: Nintendo | O9: 50-59 | P9: =IF(AND(OR(Dashboard!$B$5="All",D9=Dashboard!$B$5),OR(Dashboard!$D$5="All",N9=Dashboard!$D$5),OR(AND(C9<>"",C9>=Dashboard!$F$5,C9<=Dashboard!$H$5),AND(C9="",Dashboard!$F$5<=1980,Dashboard!$H$5>=2016))),1,0) -> 1 | Q9: =J9*P9+ROW()*0.00000001 -> 28.92
A10: New Super Mario Bros. Wii | B10: Wii | C10: 2009 | D10: Platform | E10: Nintendo | F10: 14.44 | G10: 6.94 | H10: 4.7 | I10: 2.24 | J10: 28.32 | K10: 87 | L10: 8.4 | M10: E | N10: Nintendo | O10: 80-89 | P10: =IF(AND(OR(Dashboard!$B$5="All",D10=Dashboard!$B$5),OR(Dashboard!$D$5="All",N10=Dashboard!$D$5),OR(AND(C10<>"",C10>=Dashboard!$F$5,C10<=Dashboard!$H$5),AND(C10="",Dashboard!$F$5<=1980,Dashboard!$H$5>=2016))),1,0) -> 1 | Q10: =J10*P10+ROW()*0.00000001 -> 28.32
A11: Duck Hunt | B11: NES | C11: 1984 | D11: Shooter | E11: Nintendo | F11: 26.93 | G11: 0.63 | H11: 0.28 | I11: 0.47 | J11: 28.31 | N11: Nintendo | P11: =IF(AND(OR(Dashboard!$B$5="All",D11=Dashboard!$B$5),OR(Dashboard!$D$5="All",N11=Dashboard!$D$5),OR(AND(C11<>"",C11>=Dashboard!$F$5,C11<=Dashboard!$H$5),AND(C11="",Dashboard!$F$5<=1980,Dashboard!$H$5>=2016))),1,0) -> 1 | Q11: =J11*P11+ROW()*0.00000001 -> 28.31
A12: Nintendogs | B12: DS | C12: 2005 | D12: Simulation | E12: Nintendo | F12: 9.05 | G12: 10.95 | H12: 1.93 | I12: 2.74 | J12: 24.67 | N12: Nintendo | P12: =IF(AND(OR(Dashboard!$B$5="All",D12=Dashboard!$B$5),OR(Dashboard!$D$5="All",N12=Dashboard!$D$5),OR(AND(C12<>"",C12>=Dashboard!$F$5,C12<=Dashboard!$H$5),AND(C12="",Dashboard!$F$5<=1980,Dashboard!$H$5>=2016))),1,0) -> 1 | Q12: =J12*P12+ROW()*0.00000001 -> 24.67
A13: Mario Kart DS | B13: DS | C13: 2005 | D13: Racing | E13: Nintendo | F13: 9.71 | G13: 7.47 | H13: 4.13 | I13: 1.9 | J13: 23.21 | K13: 91 | L13: 8.6 | M13: E | N13: Nintendo | O13: 90+ | P13: =IF(AND(OR(Dashboard!$B$5="All",D13=Dashboard!$B$5),OR(Dashboard!$D$5="All",N13=Dashboard!$D$5),OR(AND(C13<>"",C13>=Dashboard!$F$5,C13<=Dashboard!$H$5),AND(C13="",Dashboard!$F$5<=1980,Dashboard!$H$5>=2016))),1,0) -> 1 | Q13: =J13*P13+ROW()*0.00000001 -> 23.21
A14: Pokemon Gold/Pokemon Silver | B14: GB | C14: 1999 | D14: Role-Playing | E14: Nintendo | F14: 9 | G14: 6.18 | H14: 7.2 | I14: 0.71 | J14: 23.1 | N14: Nintendo | P14: =IF(AND(OR(Dashboard!$B$5="All",D14=Dashboard!$B$5),OR(Dashboard!$D$5="All",N14=Dashboard!$D$5),OR(AND(C14<>"",C14>=Dashboard!$F$5,C14<=Dashboard!$H$5),AND(C14="",Dashboard!$F$5<=1980,Dashboard!$H$5>=2016))),1,0) -> 1 | Q14: =J14*P14+ROW()*0.00000001 -> 23.1
A15: Wii Fit | B15: Wii | C15: 2007 | D15: Sports | E15: Nintendo | F15: 8.92 | G15: 8.03 | H15: 3.6 | I15: 2.15 | J15: 22.7 | K15: 80 | L15: 7.7 | M15: E | N15: Nintendo | O15: 70-79 | P15: =IF(AND(OR(Dashboard!$B$5="All",D15=Dashboard!$B$5),OR(Dashboard!$D$5="All",N15=Dashboard!$D$5),OR(AND(C15<>"",C15>=Dashboard!$F$5,C15<=Dashboard!$H$5),AND(C15="",Dashboard!$F$5<=1980,Dashboard!$H$5>=2016))),1,0) -> 1 | Q15: =J15*P15+ROW()*0.00000001 -> 22.7
A16: Kinect Adventures! | B16: X360 | C16: 2010 | D16: Misc | E16: Microsoft Game Studios | F16: 15 | G16: 4.89 | H16: 0.24 | I16: 1.69 | J16: 21.81 | K16: 61 | L16: 6.3 | M16: E | N16: Microsoft | O16: 60-69 | P16: =IF(AND(OR(Dashboard!$B$5="All",D16=Dashboard!$B$5),OR(Dashboard!$D$5="All",N16=Dashboard!$D$5),OR(AND(C16<>"",C16>=Dashboard!$F$5,C16<=Dashboard!$H$5),AND(C16="",Dashboard!$F$5<=1980,Dashboard!$H$5>=2016))),1,0) -> 1 | Q16: =J16*P16+ROW()*0.00000001 -> 21.81
A17: Wii Fit Plus | B17: Wii | C17: 2009 | D17: Sports | E17: Nintendo | F17: 9.01 | G17: 8.49 | H17: 2.53 | I17: 1.77 | J17: 21.79 | K17: 80 | L17: 7.4 | M17: E | N17: Nintendo | O17: 70-79 | P17: =IF(AND(OR(Dashboard!$B$5="All",D17=Dashboard!$B$5),OR(Dashboard!$D$5="All",N17=Dashboard!$D$5),OR(AND(C17<>"",C17>=Dashboard!$F$5,C17<=Dashboard!$H$5),AND(C17="",Dashboard!$F$5<=1980,Dashboard!$H$5>=2016))),1,0) -> 1 | Q17: =J17*P17+ROW()*0.00000001 -> 21.79
A18: Grand Theft Auto V | B18: PS3 | C18: 2013 | D18: Action | E18: Take-Two Interactive | F18: 7.02 | G18: 9.09 | H18: 0.98 | I18: 3.96 | J18: 21.04 | K18: 97 | L18: 8.2 | M18: M | N18: Sony | O18: 90+ | P18: =IF(AND(OR(Dashboard!$B$5="All",D18=Dashboard!$B$5),OR(Dashboard!$D$5="All",N18=Dashboard!$D$5),OR(AND(C18<>"",C18>=Dashboard!$F$5,C18<=Dashboard!$H$5),AND(C18="",Dashboard!$F$5<=1980,Dashboard!$H$5>=2016))),1,0) -> 1 | Q18: =J18*P18+ROW()*0.00000001 -> 21.04
A19: Grand Theft Auto: San Andreas | B19: PS2 | C19: 2004 | D19: Action | E19: Take-Two Interactive | F19: 9.43 | G19: 0.4 | H19: 0.41 | I19: 10.57 | J19: 20.81 | K19: 95 | L19: 9 | M19: M | N19: Sony | O19: 90+ | P19: =IF(AND(OR(Dashboard!$B$5="All",D19=Dashboard!$B$5),OR(Dashboard!$D$5="All",N19=Dashboard!$D$5),OR(AND(C19<>"",C19>=Dashboard!$F$5,C19<=Dashboard!$H$5),AND(C19="",Dashboard!$F$5<=1980,Dashboard!$H$5>=2016))),1,0) -> 1 | Q19: =J19*P19+ROW()*0.00000001 -> 20.81
A20: Super Mario World | B20: SNES | C20: 1990 | D20: Platform | E20: Nintendo | F20: 12.78 | G20: 3.75 | H20: 3.54 | I20: 0.55 | J20: 20.61 | N20: Nintendo | P20: =IF(AND(OR(Dashboard!$B$5="All",D20=Dashboard!$B$5),OR(Dashboard!$D$5="All",N20=Dashboard!$D$5),OR(AND(C20<>"",C20>=Dashboard!$F$5,C20<=Dashboard!$H$5),AND(C20="",Dashboard!$F$5<=1980,Dashboard!$H$5>=2016))),1,0) -> 1 | Q20: =J20*P20+ROW()*0.00000001 -> 20.61
A21: Brain Age: Train Your Brain in Minutes a Day | B21: DS | C21: 2005 | D21: Misc | E21: Nintendo | F21: 4.74 | G21: 9.2 | H21: 4.16 | I21: 2.04 | J21: 20.15 | K21: 77 | L21: 7.9 | M21: E | N21: Nintendo | O21: 70-79 | P21: =IF(AND(OR(Dashboard!$B$5="All",D21=Dashboard!$B$5),OR(Dashboard!$D$5="All",N21=Dashboard!$D$5),OR(AND(C21<>"",C21>=Dashboard!$F$5,C21<=Dashboard!$H$5),AND(C21="",Dashboard!$F$5<=1980,Dashboard!$H$5>=2016))),1,0) -> 1 | Q21: =J21*P21+ROW()*0.00000001 -> 20.15
A22: Pokemon Diamond/Pokemon Pearl | B22: DS | C22: 2006 | D22: Role-Playing | E22: Nintendo | F22: 6.38 | G22: 4.46 | H22: 6.04 | I22: 1.36 | J22: 18.25 | N22: Nintendo | P22: =IF(AND(OR(Dashboard!$B$5="All",D22=Dashboard!$B$5),OR(Dashboard!$D$5="All",N22=Dashboard!$D$5),OR(AND(C22<>"",C22>=Dashboard!$F$5,C22<=Dashboard!$H$5),AND(C22="",Dashboard!$F$5<=1980,Dashboard!$H$5>=2016))),1,0) -> 1 | Q22: =J22*P22+ROW()*0.00000001 -> 18.25
A23: Super Mario Land | B23: GB | C23: 1989 | D23: Platform | E23: Nintendo | F23: 10.83 | G23: 2.71 | H23: 4.18 | I23: 0.42 | J23: 18.14 | N23: Nintendo | P23: =IF(AND(OR(Dashboard!$B$5="All",D23=Dashboard!$B$5),OR(Dashboard!$D$5="All",N23=Dashboard!$D$5),OR(AND(C23<>"",C23>=Dashboard!$F$5,C23<=Dashboard!$H$5),AND(C23="",Dashboard!$F$5<=1980,Dashboard!$H$5>=2016))),1,0) -> 1 | Q23: =J23*P23+ROW()*0.00000001 -> 18.14
A24: Super Mario Bros. 3 | B24: NES | C24: 1988 | D24: Platform | E24: Nintendo | F24: 9.54 | G24: 3.44 | H24: 3.84 | I24: 0.46 | J24: 17.28 | N24: Nintendo | P24: =IF(AND(OR(Dashboard!$B$5="All",D24=Dashboard!$B$5),OR(Dashboard!$D$5="All",N24=Dashboard!$D$5),OR(AND(C24<>"",C24>=Dashboard!$F$5,C24<=Dashboard!$H$5),AND(C24="",Dashboard!$F$5<=1980,Dashboard!$H$5>=2016))),1,0) -> 1 | Q24: =J24*P24+ROW()*0.00000001 -> 17.28
A25: Grand Theft Auto V | B25: X360 | C25: 2013 | D25: Action | E25: Take-Two Interactive | F25: 9.66 | G25: 5.14 | H25: 0.06 | I25: 1.41 | J25: 16.27 | K25: 97 | L25: 8.1 | M25: M | N25: Microsoft | O25: 90+ | P25: =IF(AND(OR(Dashboard!$B$5="All",D25=Dashboard!$B$5),OR(Dashboard!$D$5="All",N25=Dashboard!$D$5),OR(AND(C25<>"",C25>=Dashboard!$F$5,C25<=Dashboard!$H$5),AND(C25="",Dashboard!$F$5<=1980,Dashboard!$H$5>=2016))),1,0) -> 1 | Q25: =J25*P25+ROW()*0.00000001 -> 16.27
A26: Grand Theft Auto: Vice City | B26: PS2 | C26: 2002 | D26: Action | E26: Take-Two Interactive | F26: 8.41 | G26: 5.49 | H26: 0.47 | I26: 1.78 | J26: 16.15 | K26: 95 | L26: 8.7 | M26: M | N26: Sony | O26: 90+ | P26: =IF(AND(OR(Dashboard!$B$5="All",D26=Dashboard!$B$5),OR(Dashboard!$D$5="All",N26=Dashboard!$D$5),OR(AND(C26<>"",C26>=Dashboard!$F$5,C26<=Dashboard!$H$5),AND(C26="",Dashboard!$F$5<=1980,Dashboard!$H$5>=2016))),1,0) -> 1 | Q26: =J26*P26+ROW()*0.00000001 -> 16.15
A27: Pokemon Ruby/Pokemon Sapphire | B27: GBA | C27: 2002 | D27: Role-Playing | E27: Nintendo | F27: 6.06 | G27: 3.9 | H27: 5.38 | I27: 0.5 | J27: 15.85 | N27: Nintendo | P27: =IF(AND(OR(Dashboard!$B$5="All",D27=Dashboard!$B$5),OR(Dashboard!$D$5="All",N27=Dashboard!$D$5),OR(AND(C27<>"",C27>=Dashboard!$F$5,C27<=Dashboard!$H$5),AND(C27="",Dashboard!$F$5<=1980,Dashboard!$H$5>=2016))),1,0) -> 1 | Q27: =J27*P27+ROW()*0.00000001 -> 15.85
A28: Brain Age 2: More Training in Minutes a Day | B28: DS | C28: 2005 | D28: Puzzle | E28: Nintendo | F28: 3.43 | G28: 5.35 | H28: 5.32 | I28: 1.18 | J28: 15.29 | K28: 77 | L28: 7.1 | M28: E | N28: Nintendo | O28: 70-79 | P28: =IF(AND(OR(Dashboard!$B$5="All",D28=Dashboard!$B$5),OR(Dashboard!$D$5="All",N28=Dashboard!$D$5),OR(AND(C28<>"",C28>=Dashboard!$F$5,C28<=Dashboard!$H$5),AND(C28="",Dashboard!$F$5<=1980,Dashboard!$H$5>=2016))),1,0) -> 1 | Q28: =J28*P28+ROW()*0.00000001 -> 15.29
A29: Pokemon Black/Pokemon White | B29: DS | C29: 2010 | D29: Role-Playing | E29: Nintendo | F29: 5.51 | G29: 3.17 | H29: 5.65 | I29: 0.8 | J29: 15.14 | N29: Nintendo | P29: =IF(AND(OR(Dashboard!$B$5="All",D29=Dashboard!$B$5),OR(Dashboard!$D$5="All",N29=Dashboard!$D$5),OR(AND(C29<>"",C29>=Dashboard!$F$5,C29<=Dashboard!$H$5),AND(C29="",Dashboard!$F$5<=1980,Dashboard!$H$5>=2016))),1,0) -> 1 | Q29: =J29*P29+ROW()*0.00000001 -> 15.14
A30: Gran Turismo 3: A-Spec | B30: PS2 | C30: 2001 | D30: Racing | E30: Sony Computer Entertainment | F30: 6.85 | G30: 5.09 | H30: 1.87 | I30: 1.16 | J30: 14.98 | K30: 95 | L30: 8.4 | M30: E | N30: Sony | O30: 90+ | P30: =IF(AND(OR(Dashboard!$B$5="All",D30=Dashboard!$B$5),OR(Dashboard!$D$5="All",N30=Dashboard!$D$5),OR(AND(C30<>"",C30>=Dashboard!$F$5,C30<=Dashboard!$H$5),AND(C30="",Dashboard!$F$5<=1980,Dashboard!$H$5>=2016))),1,0) -> 1 | Q30: =J30*P30+ROW()*0.00000001 -> 14.98
A31: Call of Duty: Modern Warfare 3 | B31: X360 | C31: 2011 | D31: Shooter | E31: Activision | F31: 9.04 | G31: 4.24 | H31: 0.13 | I31: 1.32 | J31: 14.73 | K31: 88 | L31: 3.4 | M31: M | N31: Microsoft | O31: 80-89 | P31: =IF(AND(OR(Dashboard!$B$5="All",D31=Dashboard!$B$5),OR(Dashboard!$D$5="All",N31=Dashboard!$D$5),OR(AND(C31<>"",C31>=Dashboard!$F$5,C31<=Dashboard!$H$5),AND(C31="",Dashboard!$F$5<=1980,Dashboard!$H$5>=2016))),1,0) -> 1 | Q31: =J31*P31+ROW()*0.00000001 -> 14.73
A32: Pokémon Yellow: Special Pikachu Edition | B32: GB | C32: 1998 | D32: Role-Playing | E32: Nintendo | F32: 5.89 | G32: 5.04 | H32: 3.12 | I32: 0.59 | J32: 14.64 | N32: Nintendo | P32: =IF(AND(OR(Dashboard!$B$5="All",D32=Dashboard!$B$5),OR(Dashboard!$D$5="All",N32=Dashboard!$D$5),OR(AND(C32<>"",C32>=Dashboard!$F$5,C32<=Dashboard!$H$5),AND(C32="",Dashboard!$F$5<=1980,Dashboard!$H$5>=2016))),1,0) -> 1 | Q32: =J32*P32+ROW()*0.00000001 -> 14.64
A33: Call of Duty: Black Ops 3 | B33: PS4 | C33: 2015 | D33: Shooter | E33: Activision | F33: 6.03 | G33: 5.86 | H33: 0.36 | I33: 2.38 | J33: 14.63 | N33: Sony | P33: =IF(AND(OR(Dashboard!$B$5="All",D33=Dashboard!$B$5),OR(Dashboard!$D$5="All",N33=Dashboard!$D$5),OR(AND(C33<>"",C33>=Dashboard!$F$5,C33<=Dashboard!$H$5),AND(C33="",Dashboard!$F$5<=1980,Dashboard!$H$5>=2016))),1,0) -> 1 | Q33: =J33*P33+ROW()*0.00000001 -> 14.63
A34: Call of Duty: Black Ops | B34: X360 | C34: 2010 | D34: Shooter | E34: Activision | F34: 9.7 | G34: 3.68 | H34: 0.11 | I34: 1.13 | J34: 14.61 | K34: 87 | L34: 6.3 | M34: M | N34: Microsoft | O34: 80-89 | P34: =IF(AND(OR(Dashboard!$B$5="All",D34=Dashboard!$B$5),OR(Dashboard!$D$5="All",N34=Dashboard!$D$5),OR(AND(C34<>"",C34>=Dashboard!$F$5,C34<=Dashboard!$H$5),AND(C34="",Dashboard!$F$5<=1980,Dashboard!$H$5>=2016))),1,0) -> 1 | Q34: =J34*P34+ROW()*0.00000001 -> 14.61
A35: Pokemon X/Pokemon Y | B35: 3DS | C35: 2013 | D35: Role-Playing | E35: Nintendo | F35: 5.28 | G35: 4.19 | H35: 4.35 | I35: 0.78 | J35: 14.6 | N35: Nintendo | P35: =IF(AND(OR(Dashboard!$B$5="All",D35=Dashboard!$B$5),OR(Dashboard!$D$5="All",N35=Dashboard!$D$5),OR(AND(C35<>"",C35>=Dashboard!$F$5,C35<=Dashboard!$H$5),AND(C35="",Dashboard!$F$5<=1980,Dashboard!$H$5>=2016))),1,0) -> 1 | Q35: =J35*P35+ROW()*0.00000001 -> 14.6
A36: Call of Duty: Black Ops II | B36: PS3 | C36: 2012 | D36: Shooter | E36: Activision | F36: 4.99 | G36: 5.73 | H36: 0.65 | I36: 2.42 | J36: 13.79 | K36: 83 | L36: 5.3 | M36: M | N36: Sony | O36: 80-89 | P36: =IF(AND(OR(Dashboard!$B$5="All",D36=Dashboard!$B$5),OR(Dashboard!$D$5="All",N36=Dashboard!$D$5),OR(AND(C36<>"",C36>=Dashboard!$F$5,C36<=Dashboard!$H$5),AND(C36="",Dashboard!$F$5<=1980,Dashboard!$H$5>=2016))),1,0) -> 1 | Q36: =J36*P36+ROW()*0.00000001 -> 13.79
A37: Call of Duty: Black Ops II | B37: X360 | C37: 2012 | D37: Shooter | E37: Activision | F37: 8.25 | G37: 4.24 | H37: 0.07 | I37: 1.12 | J37: 13.67 | K37: 83 | L37: 4.8 | M37: M | N37: Microsoft | O37: 80-89 | P37: =IF(AND(OR(Dashboard!$B$5="All",D37=Dashboard!$B$5),OR(Dashboard!$D$5="All",N37=Dashboard!$D$5),OR(AND(C37<>"",C37>=Dashboard!$F$5,C37<=Dashboard!$H$5),AND(C37="",Dashboard!$F$5<=1980,Dashboard!$H$5>=2016))),1,0) -> 1 | Q37: =J37*P37+ROW()*0.00000001 -> 13.67
A38: Call of Duty: Modern Warfare 2 | B38: X360 | C38: 2009 | D38: Shooter | E38: Activision | F38: 8.52 | G38: 3.59 | H38: 0.08 | I38: 1.28 | J38: 13.47 | K38: 94 | L38: 6.3 | M38: M | N38: Microsoft | O38: 90+ | P38: =IF(AND(OR(Dashboard!$B$5="All",D38=Dashboard!$B$5),OR(Dashboard!$D$5="All",N38=Dashboard!$D$5),OR(AND(C38<>"",C38>=Dashboard!$F$5,C38<=Dashboard!$H$5),AND(C38="",Dashboard!$F$5<=1980,Dashboard!$H$5>=2016))),1,0) -> 1 | Q38: =J38*P38+ROW()*0.00000001 -> 13.47
A39: Call of Duty: Modern Warfare 3 | B39: PS3 | C39: 2011 | D39: Shooter | E39: Activision | F39: 5.54 | G39: 5.73 | H39: 0.49 | I39: 1.57 | J39: 13.32 | K39: 88 | L39: 3.2 | M39: M | N39: Sony | O39: 80-89 | P39: =IF(AND(OR(Dashboard!$B$5="All",D39=Dashboard!$B$5),OR(Dashboard!$D$5="All",N39=Dashboard!$D$5),OR(AND(C39<>"",C39>=Dashboard!$F$5,C39<=Dashboard!$H$5),AND(C39="",Dashboard!$F$5<=1980,Dashboard!$H$5>=2016))),1,0) -> 1 | Q39: =J39*P39+ROW()*0.00000001 -> 13.32
A40: Grand Theft Auto III | B40: PS2 | C40: 2001 | D40: Action | E40: Take-Two Interactive | F40: 6.99 | G40: 4.51 | H40: 0.3 | I40: 1.3 | J40: 13.1 | K40: 97 | L40: 8.5 | M40: M | N40: Sony | O40: 90+ | P40: =IF(AND(OR(Dashboard!$B$5="All",D40=Dashboard!$B$5),OR(Dashboard!$D$5="All",N40=Dashboard!$D$5),OR(AND(C40<>"",C40>=Dashboard!$F$5,C40<=Dashboard!$H$5),AND(C40="",Dashboard!$F$5<=1980,Dashboard!$H$5>=2016))),1,0) -> 1 | Q40: =J40*P40+ROW()*0.00000001 -> 13.1
...

Sheet Calc
A1: Helper tables feeding the Dashboard (all formulas react to the Dashboard filters). Do not edit.
A2: Genre | B2: Releases | C2: Sales (M) | D2: Avg per release (M) | F2: Year | G2: Releases | H2: Sales (M) | J2: Region | K2: Sales (M) | M2: Critic band | N2: Avg sales per release (M) | P2: Platform | Q2: Sales (M) | R2: Sort key | T2: Rank | U2: Top platforms | V2: Sales (M) | X2: Publisher | Y2: Sales (M) | Z2: Sort key | AB2: Rank | AC2: Top publishers | AD2: Sales (M) | AF2: Rank | AG2: Top releases | AH2: Sales (M)
A3: Action | B3: =COUNTIFS(Data!$D$2:$D$16716,A3,Data!$P$2:$P$16716,1) -> 3370 | C3: =SUMIFS(Data!$J$2:$J$16716,Data!$D$2:$D$16716,A3,Data!$P$2:$P$16716,1) -> 1745.27 | D3: =IF(B3=0,0,C3/B3) -> 0.51788427 | F3: 1980 | G3: =COUNTIFS(Data!$C$2:$C$16716,F3,Data!$P$2:$P$16716,1) -> 9 | H3: =SUMIFS(Data!$J$2:$J$16716,Data!$C$2:$C$16716,F3,Data!$P$2:$P$16716,1) -> 11.38 | J3: North America | K3: =SUMIFS(Data!$F$2:$F$16716,Data!$P$2:$P$16716,1) -> 4400.84 | M3: 0-49 | N3: =IFERROR(AVERAGEIFS(Data!$J$2:$J$16716,Data!$O$2:$O$16716,M3,Data!$P$2:$P$16716,1),0) -> 0.23077273 | P3: PS2 | Q3: =SUMIFS(Data!$J$2:$J$16716,Data!$B$2:$B$16716,P3,Data!$P$2:$P$16716,1) -> 1255.64 | R3: =Q3+ROW()*0.000000001 -> 1255.64 | T3: 1 | U3: =IF(V3=0,"",INDEX($P$3:$P$33,MATCH(LARGE($R$3:$R$33,T3),$R$3:$R$33,0))) -> PS2 | V3: =INDEX($Q$3:$Q$33,MATCH(LARGE($R$3:$R$33,T3),$R$3:$R$33,0)) -> 1255.64 | X3: Nintendo | Y3: =SUMIFS(Data!$J$2:$J$16716,Data!$E$2:$E$16716,X3,Data!$P$2:$P$16716,1) -> 1788.81 | Z3: =Y3+ROW()*0.000000001 -> 1788.81 | AB3: 1 | AC3: =IF(AD3=0,"",INDEX($X$3:$X$574,MATCH(LARGE($Z$3:$Z$574,AB3),$Z$3:$Z$574,0))) -> Nintendo | AD3: =INDEX($Y$3:$Y$574,MATCH(LARGE($Z$3:$Z$574,AB3),$Z$3:$Z$574,0)) -> 1788.81 | AF3: 1 | AG3: =IF(AH3=0,"",INDEX(Data!$A$2:$A$16716,MATCH(LARGE(Data!$Q$2:$Q$16716,AF3),Data!$Q$2:$Q$16716,0))&" ("&INDEX(Data!$B$2:$B$16716,MATCH(LARGE(Data!$Q$2:$Q$16716,AF3),Data!$Q$2:$Q$16716,0))&")") -> Wii Sports (Wii) | AH3: =INDEX(Data!$J$2:$J$16716,MATCH(LARGE(Data!$Q$2:$Q$16716,AF3),Data!$Q$2:$Q$16716,0))*INDEX(Data!$P$2:$P$16716,MATCH(LARGE(Data!$Q$2:$Q$16716,AF3),Data!$Q$2:$Q$16716,0)) -> 82.53
A4: Sports | B4: =COUNTIFS(Data!$D$2:$D$16716,A4,Data!$P$2:$P$16716,1) -> 2347 | C4: =SUMIFS(Data!$J$2:$J$16716,Data!$D$2:$D$16716,A4,Data!$P$2:$P$16716,1) -> 1332 | D4: =IF(B4=0,0,C4/B4) -> 0.56753302 | F4: 1981 | G4: =COUNTIFS(Data!$C$2:$C$16716,F4,Data!$P$2:$P$16716,1) -> 46 | H4: =SUMIFS(Data!$J$2:$J$16716,Data!$C$2:$C$16716,F4,Data!$P$2:$P$16716,1) -> 35.77 | J4: Europe | K4: =SUMIFS(Data!$G$2:$G$16716,Data!$P$2:$P$16716,1) -> 2424.14 | M4: 50-59 | N4: =IFERROR(AVERAGEIFS(Data!$J$2:$J$16716,Data!$O$2:$O$16716,M4,Data!$P$2:$P$16716,1),0) -> 0.30128788 | P4: X360 | Q4: =SUMIFS(Data!$J$2:$J$16716,Data!$B$2:$B$16716,P4,Data!$P$2:$P$16716,1) -> 971.63 | R4: =Q4+ROW()*0.000000001 -> 971.63 | T4: 2 | U4: =IF(V4=0,"",INDEX($P$3:$P$33,MATCH(LARGE($R$3:$R$33,T4),$R$3:$R$33,0))) -> X360 | V4: =INDEX($Q$3:$Q$33,MATCH(LARGE($R$3:$R$33,T4),$R$3:$R$33,0)) -> 971.63 | X4: Electronic Arts | Y4: =SUMIFS(Data!$J$2:$J$16716,Data!$E$2:$E$16716,X4,Data!$P$2:$P$16716,1) -> 1116.96 | Z4: =Y4+ROW()*0.000000001 -> 1116.96 | AB4: 2 | AC4: =IF(AD4=0,"",INDEX($X$3:$X$574,MATCH(LARGE($Z$3:$Z$574,AB4),$Z$3:$Z$574,0))) -> Electronic Arts | AD4: =INDEX($Y$3:$Y$574,MATCH(LARGE($Z$3:$Z$574,AB4),$Z$3:$Z$574,0)) -> 1116.96 | AF4: 2 | AG4: =IF(AH4=0,"",INDEX(Data!$A$2:$A$16716,MATCH(LARGE(Data!$Q$2:$Q$16716,AF4),Data!$Q$2:$Q$16716,0))&" ("&INDEX(Data!$B$2:$B$16716,MATCH(LARGE(Data!$Q$2:$Q$16716,AF4),Data!$Q$2:$Q$16716,0))&")") -> Super Mario Bros. (NES) | AH4: =INDEX(Data!$J$2:$J$16716,MATCH(LARGE(Data!$Q$2:$Q$16716,AF4),Data!$Q$2:$Q$16716,0))*INDEX(Data!$P$2:$P$16716,MATCH(LARGE(Data!$Q$2:$Q$16716,AF4),Data!$Q$2:$Q$16716,0)) -> 40.24
A5: Shooter | B5: =COUNTIFS(Data!$D$2:$D$16716,A5,Data!$P$2:$P$16716,1) -> 1323 | C5: =SUMIFS(Data!$J$2:$J$16716,Data!$D$2:$D$16716,A5,Data!$P$2:$P$16716,1) -> 1052.94 | D5: =IF(B5=0,0,C5/B5) -> 0.79587302 | F5: 1982 | G5: =COUNTIFS(Data!$C$2:$C$16716,F5,Data!$P$2:$P$16716,1) -> 36 | H5: =SUMIFS(Data!$J$2:$J$16716,Data!$C$2:$C$16716,F5,Data!$P$2:$P$16716,1) -> 28.86 | J5: Japan | K5: =SUMIFS(Data!$H$2:$H$16716,Data!$P$2:$P$16716,1) -> 1297.4 | M5: 60-69 | N5: =IFERROR(AVERAGEIFS(Data!$J$2:$J$16716,Data!$O$2:$O$16716,M5,Data!$P$2:$P$16716,1),0) -> 0.37993843 | P5: PS3 | Q5: =SUMIFS(Data!$J$2:$J$16716,Data!$B$2:$B$16716,P5,Data!$P$2:$P$16716,1) -> 939.43 | R5: =Q5+ROW()*0.000000001 -> 939.43 | T5: 3 | U5: =IF(V5=0,"",INDEX($P$3:$P$33,MATCH(LARGE($R$3:$R$33,T5),$R$3:$R$33,0))) -> PS3 | V5: =INDEX($Q$3:$Q$33,MATCH(LARGE($R$3:$R$33,T5),$R$3:$R$33,0)) -> 939.43 | X5: Activision | Y5: =SUMIFS(Data!$J$2:$J$16716,Data!$E$2:$E$16716,X5,Data!$P$2:$P$16716,1) -> 738.11 | Z5: =Y5+ROW()*0.000000001 -> 738.11 | AB5: 3 | AC5: =IF(AD5=0,"",INDEX($X$3:$X$574,MATCH(LARGE($Z$3:$Z$574,AB5),$Z$3:$Z$574,0))) -> Activision | AD5: =INDEX($Y$3:$Y$574,MATCH(LARGE($Z$3:$Z$574,AB5),$Z$3:$Z$574,0)) -> 738.11 | AF5: 3 | AG5: =IF(AH5=0,"",INDEX(Data!$A$2:$A$16716,MATCH(LARGE(Data!$Q$2:$Q$16716,AF5),Data!$Q$2:$Q$16716,0))&" ("&INDEX(Data!$B$2:$B$16716,MATCH(LARGE(Data!$Q$2:$Q$16716,AF5),Data!$Q$2:$Q$16716,0))&")") -> Mario Kart Wii (Wii) | AH5: =INDEX(Data!$J$2:$J$16716,MATCH(LARGE(Data!$Q$2:$Q$16716,AF5),Data!$Q$2:$Q$16716,0))*INDEX(Data!$P$2:$P$16716,MATCH(LARGE(Data!$Q$2:$Q$16716,AF5),Data!$Q$2:$Q$16716,0)) -> 35.52
A6: Role-Playing | B6: =COUNTIFS(Data!$D$2:$D$16716,A6,Data!$P$2:$P$16716,1) -> 1500 | C6: =SUMIFS(Data!$J$2:$J$16716,Data!$D$2:$D$16716,A6,Data!$P$2:$P$16716,1) -> 934.4 | D6: =IF(B6=0,0,C6/B6) -> 0.62293333 | F6: 1983 | G6: =COUNTIFS(Data!$C$2:$C$16716,F6,Data!$P$2:$P$16716,1) -> 17 | H6: =SUMIFS(Data!$J$2:$J$16716,Data!$C$2:$C$16716,F6,Data!$P$2:$P$16716,1) -> 16.79 | J6: Other | K6: =SUMIFS(Data!$I$2:$I$16716,Data!$P$2:$P$16716,1) -> 791.26 | M6: 70-79 | N6: =IFERROR(AVERAGEIFS(Data!$J$2:$J$16716,Data!$O$2:$O$16716,M6,Data!$P$2:$P$16716,1),0) -> 0.67607509 | P6: Wii | Q6: =SUMIFS(Data!$J$2:$J$16716,Data!$B$2:$B$16716,P6,Data!$P$2:$P$16716,1) -> 908.13 | R6: =Q6+ROW()*0.000000001 -> 908.13 | T6: 4 | U6: =IF(V6=0,"",INDEX($P$3:$P$33,MATCH(LARGE($R$3:$R$33,T6),$R$3:$R$33,0))) -> Wii | V6: =INDEX($Q$3:$Q$33,MATCH(LARGE($R$3:$R$33,T6),$R$3:$R$33,0)) -> 908.13 | X6: Sony Computer Entertainment | Y6: =SUMIFS(Data!$J$2:$J$16716,Data!$E$2:$E$16716,X6,Data!$P$2:$P$16716,1) -> 631.11 | Z6: =Y6+ROW()*0.000000001 -> 631.11 | AB6: 4 | AC6: =IF(AD6=0,"",INDEX($X$3:$X$574,MATCH(LARGE($Z$3:$Z$574,AB6),$Z$3:$Z$574,0))) -> Sony Computer Entertainment | AD6: =INDEX($Y$3:$Y$574,MATCH(LARGE($Z$3:$Z$574,AB6),$Z$3:$Z$574,0)) -> 631.11 | AF6: 4 | AG6: =IF(AH6=0,"",INDEX(Data!$A$2:$A$16716,MATCH(LARGE(Data!$Q$2:$Q$16716,AF6),Data!$Q$2:$Q$16716,0))&" ("&INDEX(Data!$B$2:$B$16716,MATCH(LARGE(Data!$Q$2:$Q$16716,AF6),Data!$Q$2:$Q$16716,0))&")") -> Wii Sports Resort (Wii) | AH6: =INDEX(Data!$J$2:$J$16716,MATCH(LARGE(Data!$Q$2:$Q$16716,AF6),Data!$Q$2:$Q$16716,0))*INDEX(Data!$P$2:$P$16716,MATCH(LARGE(Data!$Q$2:$Q$16716,AF6),Data!$Q$2:$Q$16716,0)) -> 32.77
A7: Platform | B7: =COUNTIFS(Data!$D$2:$D$16716,A7,Data!$P$2:$P$16716,1) -> 887 | C7: =SUMIFS(Data!$J$2:$J$16716,Data!$D$2:$D$16716,A7,Data!$P$2:$P$16716,1) -> 828.08 | D7: =IF(B7=0,0,C7/B7) -> 0.93357384 | F7: 1984 | G7: =COUNTIFS(Data!$C$2:$C$16716,F7,Data!$P$2:$P$16716,1) -> 14 | H7: =SUMIFS(Data!$J$2:$J$16716,Data!$C$2:$C$16716,F7,Data!$P$2:$P$16716,1) -> 50.36 | M7: 80-89 | N7: =IFERROR(AVERAGEIFS(Data!$J$2:$J$16716,Data!$O$2:$O$16716,M7,Data!$P$2:$P$16716,1),0) -> 1.2463546 | P7: DS | Q7: =SUMIFS(Data!$J$2:$J$16716,Data!$B$2:$B$16716,P7,Data!$P$2:$P$16716,1) -> 807.1 | R7: =Q7+ROW()*0.000000001 -> 807.1 | T7: 5 | U7: =IF(V7=0,"",INDEX($P$3:$P$33,MATCH(LARGE($R$3:$R$33,T7),$R$3:$R$33,0))) -> DS | V7: =INDEX($Q$3:$Q$33,MATCH(LARGE($R$3:$R$33,T7),$R$3:$R$33,0)) -> 807.1 | X7: Ubisoft | Y7: =SUMIFS(Data!$J$2:$J$16716,Data!$E$2:$E$16716,X7,Data!$P$2:$P$16716,1) -> 476.07 | Z7: =Y7+ROW()*0.000000001 -> 476.07 | AB7: 5 | AC7: =IF(AD7=0,"",INDEX($X$3:$X$574,MATCH(LARGE($Z$3:$Z$574,AB7),$Z$3:$Z$574,0))) -> Ubisoft | AD7: =INDEX($Y$3:$Y$574,MATCH(LARGE($Z$3:$Z$574,AB7),$Z$3:$Z$574,0)) -> 476.07 | AF7: 5 | AG7: =IF(AH7=0,"",INDEX(Data!$A$2:$A$16716,MATCH(LARGE(Data!$Q$2:$Q$16716,AF7),Data!$Q$2:$Q$16716,0))&" ("&INDEX(Data!$B$2:$B$16716,MATCH(LARGE(Data!$Q$2:$Q$16716,AF7),Data!$Q$2:$Q$16716,0))&")") -> Pokemon Red/Pokemon Blue (GB) | AH7: =INDEX(Data!$J$2:$J$16716,MATCH(LARGE(Data!$Q$2:$Q$16716,AF7),Data!$Q$2:$Q$16716,0))*INDEX(Data!$P$2:$P$16716,MATCH(LARGE(Data!$Q$2:$Q$16716,AF7),Data!$Q$2:$Q$16716,0)) -> 31.37
A8: Misc | B8: =COUNTIFS(Data!$D$2:$D$16716,A8,Data!$P$2:$P$16716,1) -> 1750 | C8: =SUMIFS(Data!$J$2:$J$16716,Data!$D$2:$D$16716,A8,Data!$P$2:$P$16716,1) -> 803.18 | D8: =IF(B8=0,0,C8/B8) -> 0.45896 | F8: 1985 | G8: =COUNTIFS(Data!$C$2:$C$16716,F8,Data!$P$2:$P$16716,1) -> 14 | H8: =SUMIFS(Data!$J$2:$J$16716,Data!$C$2:$C$16716,F8,Data!$P$2:$P$16716,1) -> 53.94 | M8: 90+ | N8: =IFERROR(AVERAGEIFS(Data!$J$2:$J$16716,Data!$O$2:$O$16716,M8,Data!$P$2:$P$16716,1),0) -> 3.2285214 | P8: PS | Q8: =SUMIFS(Data!$J$2:$J$16716,Data!$B$2:$B$16716,P8,Data!$P$2:$P$16716,1) -> 730.68 | R8: =Q8+ROW()*0.000000001 -> 730.68 | T8: 6 | U8: =IF(V8=0,"",INDEX($P$3:$P$33,MATCH(LARGE($R$3:$R$33,T8),$R$3:$R$33,0))) -> PS | V8: =INDEX($Q$3:$Q$33,MATCH(LARGE($R$3:$R$33,T8),$R$3:$R$33,0)) -> 730.68 | X8: Take-Two Interactive | Y8: =SUMIFS(Data!$J$2:$J$16716,Data!$E$2:$E$16716,X8,Data!$P$2:$P$16716,1) -> 403.82 | Z8: =Y8+ROW()*0.000000001 -> 403.82 | AB8: 6 | AC8: =IF(AD8=0,"",INDEX($X$3:$X$574,MATCH(LARGE($Z$3:$Z$574,AB8),$Z$3:$Z$574,0))) -> Take-Two Interactive | AD8: =INDEX($Y$3:$Y$574,MATCH(LARGE($Z$3:$Z$574,AB8),$Z$3:$Z$574,0)) -> 403.82 | AF8: 6 | AG8: =IF(AH8=0,"",INDEX(Data!$A$2:$A$16716,MATCH(LARGE(Data!$Q$2:$Q$16716,AF8),Data!$Q$2:$Q$16716,0))&" ("&INDEX(Data!$B$2:$B$16716,MATCH(LARGE(Data!$Q$2:$Q$16716,AF8),Data!$Q$2:$Q$16716,0))&")") -> Tetris (GB) | AH8: =INDEX(Data!$J$2:$J$16716,MATCH(LARGE(Data!$Q$2:$Q$16716,AF8),Data!$Q$2:$Q$16716,0))*INDEX(Data!$P$2:$P$16716,MATCH(LARGE(Data!$Q$2:$Q$16716,AF8),Data!$Q$2:$Q$16716,0)) -> 30.26
A9: Racing | B9: =COUNTIFS(Data!$D$2:$D$16716,A9,Data!$P$2:$P$16716,1) -> 1249 | C9: =SUMIFS(Data!$J$2:$J$16716,Data!$D$2:$D$16716,A9,Data!$P$2:$P$16716,1) -> 728.9 | D9: =IF(B9=0,0,C9/B9) -> 0.58358687 | F9: 1986 | G9: =COUNTIFS(Data!$C$2:$C$16716,F9,Data!$P$2:$P$16716,1) -> 21 | H9: =SUMIFS(Data!$J$2:$J$16716,Data!$C$2:$C$16716,F9,Data!$P$2:$P$16716,1) -> 37.07 | P9: GBA | Q9: =SUMIFS(Data!$J$2:$J$16716,Data!$B$2:$B$16716,P9,Data!$P$2:$P$16716,1) -> 318.5 | R9: =Q9+ROW()*0.000000001 -> 318.5 | T9: 7 | U9: =IF(V9=0,"",INDEX($P$3:$P$33,MATCH(LARGE($R$3:$R$33,T9),$R$3:$R$33,0))) -> GBA | V9: =INDEX($Q$3:$Q$33,MATCH(LARGE($R$3:$R$33,T9),$R$3:$R$33,0)) -> 318.5 | X9: THQ | Y9: =SUMIFS(Data!$J$2:$J$16716,Data!$E$2:$E$16716,X9,Data!$P$2:$P$16716,1) -> 338.44 | Z9: =Y9+ROW()*0.000000001 -> 338.44 | AB9: 7 | AC9: =IF(AD9=0,"",INDEX($X$3:$X$574,MATCH(LARGE($Z$3:$Z$574,AB9),$Z$3:$Z$574,0))) -> THQ | AD9: =INDEX($Y$3:$Y$574,MATCH(LARGE($Z$3:$Z$574,AB9),$Z$3:$Z$574,0)) -> 338.44 | AF9: 7 | AG9: =IF(AH9=0,"",INDEX(Data!$A$2:$A$16716,MATCH(LARGE(Data!$Q$2:$Q$16716,AF9),Data!$Q$2:$Q$16716,0))&" ("&INDEX(Data!$B$2:$B$16716,MATCH(LARGE(Data!$Q$2:$Q$16716,AF9),Data!$Q$2:$Q$16716,0))&")") -> New Super Mario Bros. (DS) | AH9: =INDEX(Data!$J$2:$J$16716,MATCH(LARGE(Data!$Q$2:$Q$16716,AF9),Data!$Q$2:$Q$16716,0))*INDEX(Data!$P$2:$P$16716,MATCH(LARGE(Data!$Q$2:$Q$16716,AF9),Data!$Q$2:$Q$16716,0)) -> 29.8
A10: Fighting | B10: =COUNTIFS(Data!$D$2:$D$16716,A10,Data!$P$2:$P$16716,1) -> 849 | C10: =SUMIFS(Data!$J$2:$J$16716,Data!$D$2:$D$16716,A10,Data!$P$2:$P$16716,1) -> 447.48 | D10: =IF(B10=0,0,C10/B10) -> 0.52706714 | F10: 1987 | G10: =COUNTIFS(Data!$C$2:$C$16716,F10,Data!$P$2:$P$16716,1) -> 16 | H10: =SUMIFS(Data!$J$2:$J$16716,Data!$C$2:$C$16716,F10,Data!$P$2:$P$16716,1) -> 21.74 | P10: PS4 | Q10: =SUMIFS(Data!$J$2:$J$16716,Data!$B$2:$B$16716,P10,Data!$P$2:$P$16716,1) -> 314.23 | R10: =Q10+ROW()*0.000000001 -> 314.23 | T10: 8 | U10: =IF(V10=0,"",INDEX($P$3:$P$33,MATCH(LARGE($R$3:$R$33,T10),$R$3:$R$33,0))) -> PS4 | V10: =INDEX($Q$3:$Q$33,MATCH(LARGE($R$3:$R$33,T10),$R$3:$R$33,0)) -> 314.23 | X10: Konami Digital Entertainment | Y10: =SUMIFS(Data!$J$2:$J$16716,Data!$E$2:$E$16716,X10,Data!$P$2:$P$16716,1) -> 282.39 | Z10: =Y10+ROW()*0.000000001 -> 282.39 | AB10: 8 | AC10: =IF(AD10=0,"",INDEX($X$3:$X$574,MATCH(LARGE($Z$3:$Z$574,AB10),$Z$3:$Z$574,0))) -> Konami Digital Entertainment | AD10: =INDEX($Y$3:$Y$574,MATCH(LARGE($Z$3:$Z$574,AB10),$Z$3:$Z$574,0)) -> 282.39 | AF10: 8 | AG10: =IF(AH10=0,"",INDEX(Data!$A$2:$A$16716,MATCH(LARGE(Data!$Q$2:$Q$16716,AF10),Data!$Q$2:$Q$16716,0))&" ("&INDEX(Data!$B$2:$B$16716,MATCH(LARGE(Data!$Q$2:$Q$16716,AF10),Data!$Q$2:$Q$16716,0))&")") -> Wii Play (Wii) | AH10: =INDEX(Data!$J$2:$J$16716,MATCH(LARGE(Data!$Q$2:$Q$16716,AF10),Data!$Q$2:$Q$16716,0))*INDEX(Data!$P$2:$P$16716,MATCH(LARGE(Data!$Q$2:$Q$16716,AF10),Data!$Q$2:$Q$16716,0)) -> 28.92
A11: Simulation | B11: =COUNTIFS(Data!$D$2:$D$16716,A11,Data!$P$2:$P$16716,1) -> 874 | C11: =SUMIFS(Data!$J$2:$J$16716,Data!$D$2:$D$16716,A11,Data!$P$2:$P$16716,1) -> 390.42 | D11: =IF(B11=0,0,C11/B11) -> 0.44670481 | F11: 1988 | G11: =COUNTIFS(Data!$C$2:$C$16716,F11,Data!$P$2:$P$16716,1) -> 15 | H11: =SUMIFS(Data!$J$2:$J$16716,Data!$C$2:$C$16716,F11,Data!$P$2:$P$16716,1) -> 47.22 | P11: PSP | Q11: =SUMIFS(Data!$J$2:$J$16716,Data!$B$2:$B$16716,P11,Data!$P$2:$P$16716,1) -> 294.3 | R11: =Q11+ROW()*0.000000001 -> 294.3 | T11: 9 | U11: =IF(V11=0,"",INDEX($P$3:$P$33,MATCH(LARGE($R$3:$R$33,T11),$R$3:$R$33,0))) -> PSP | V11: =INDEX($Q$3:$Q$33,MATCH(LARGE($R$3:$R$33,T11),$R$3:$R$33,0)) -> 294.3 | X11: Sega | Y11: =SUMIFS(Data!$J$2:$J$16716,Data!$E$2:$E$16716,X11,Data!$P$2:$P$16716,1) -> 270.83 | Z11: =Y11+ROW()*0.000000001 -> 270.83 | AB11: 9 | AC11: =IF(AD11=0,"",INDEX($X$3:$X$574,MATCH(LARGE($Z$3:$Z$574,AB11),$Z$3:$Z$574,0))) -> Sega | AD11: =INDEX($Y$3:$Y$574,MATCH(LARGE($Z$3:$Z$574,AB11),$Z$3:$Z$574,0)) -> 270.83 | AF11: 9 | AG11: =IF(AH11=0,"",INDEX(Data!$A$2:$A$16716,MATCH(LARGE(Data!$Q$2:$Q$16716,AF11),Data!$Q$2:$Q$16716,0))&" ("&INDEX(Data!$B$2:$B$16716,MATCH(LARGE(Data!$Q$2:$Q$16716,AF11),Data!$Q$2:$Q$16716,0))&")") -> New Super Mario Bros. Wii (Wii) | AH11: =INDEX(Data!$J$2:$J$16716,MATCH(LARGE(Data!$Q$2:$Q$16716,AF11),Data!$Q$2:$Q$16716,0))*INDEX(Data!$P$2:$P$16716,MATCH(LARGE(Data!$Q$2:$Q$16716,AF11),Data!$Q$2:$Q$16716,0)) -> 28.32
A12: Puzzle | B12: =COUNTIFS(Data!$D$2:$D$16716,A12,Data!$P$2:$P$16716,1) -> 580 | C12: =SUMIFS(Data!$J$2:$J$16716,Data!$D$2:$D$16716,A12,Data!$P$2:$P$16716,1) -> 243.02 | D12: =IF(B12=0,0,C12/B12) -> 0.419 | F12: 1989 | G12: =COUNTIFS(Data!$C$2:$C$16716,F12,Data!$P$2:$P$16716,1) -> 17 | H12: =SUMIFS(Data!$J$2:$J$16716,Data!$C$2:$C$16716,F12,Data!$P$2:$P$16716,1) -> 73.45 | P12: PC | Q12: =SUMIFS(Data!$J$2:$J$16716,Data!$B$2:$B$16716,P12,Data!$P$2:$P$16716,1) -> 260.3 | R12: =Q12+ROW()*0.000000001 -> 260.3 | T12: 10 | U12: =IF(V12=0,"",INDEX($P$3:$P$33,MATCH(LARGE($R$3:$R$33,T12),$R$3:$R$33,0))) -> PC | V12: =INDEX($Q$3:$Q$33,MATCH(LARGE($R$3:$R$33,T12),$R$3:$R$33,0)) -> 260.3 | X12: Namco Bandai Games | Y12: =SUMIFS(Data!$J$2:$J$16716,Data!$E$2:$E$16716,X12,Data!$P$2:$P$16716,1) -> 254.62 | Z12: =Y12+ROW()*0.000000001 -> 254.62 | AB12: 10 | AC12: =IF(AD12=0,"",INDEX($X$3:$X$574,MATCH(LARGE($Z$3:$Z$574,AB12),$Z$3:$Z$574,0))) -> Namco Bandai Games | AD12: =INDEX($Y$3:$Y$574,MATCH(LARGE($Z$3:$Z$574,AB12),$Z$3:$Z$574,0)) -> 254.62 | AF12: 10 | AG12: =IF(AH12=0,"",INDEX(Data!$A$2:$A$16716,MATCH(LARGE(Data!$Q$2:$Q$16716,AF12),Data!$Q$2:$Q$16716,0))&" ("&INDEX(Data!$B$2:$B$16716,MATCH(LARGE(Data!$Q$2:$Q$16716,AF12),Data!$Q$2:$Q$16716,0))&")") -> Duck Hunt (NES) | AH12: =INDEX(Data!$J$2:$J$16716,MATCH(LARGE(Data!$Q$2:$Q$16716,AF12),Data!$Q$2:$Q$16716,0))*INDEX(Data!$P$2:$P$16716,MATCH(LARGE(Data!$Q$2:$Q$16716,AF12),Data!$Q$2:$Q$16716,0)) -> 28.31
A13: Adventure | B13: =COUNTIFS(Data!$D$2:$D$16716,A13,Data!$P$2:$P$16716,1) -> 1303 | C13: =SUMIFS(Data!$J$2:$J$16716,Data!$D$2:$D$16716,A13,Data!$P$2:$P$16716,1) -> 237.69 | D13: =IF(B13=0,0,C13/B13) -> 0.1824175 | F13: 1990 | G13: =COUNTIFS(Data!$C$2:$C$16716,F13,Data!$P$2:$P$16716,1) -> 16 | H13: =SUMIFS(Data!$J$2:$J$16716,Data!$C$2:$C$16716,F13,Data!$P$2:$P$16716,1) -> 49.39 | P13: 3DS | Q13: =SUMIFS(Data!$J$2:$J$16716,Data!$B$2:$B$16716,P13,Data!$P$2:$P$16716,1) -> 259.09 | R13: =Q13+ROW()*0.000000001 -> 259.09 | X13: Microsoft Game Studios | Y13: =SUMIFS(Data!$J$2:$J$16716,Data!$E$2:$E$16716,X13,Data!$P$2:$P$16716,1) -> 248.32 | Z13: =Y13+ROW()*0.000000001 -> 248.32
A14: Strategy | B14: =COUNTIFS(Data!$D$2:$D$16716,A14,Data!$P$2:$P$16716,1) -> 683 | C14: =SUMIFS(Data!$J$2:$J$16716,Data!$D$2:$D$16716,A14,Data!$P$2:$P$16716,1) -> 174.5 | D14: =IF(B14=0,0,C14/B14) -> 0.25549048 | F14: 1991 | G14: =COUNTIFS(Data!$C$2:$C$16716,F14,Data!$P$2:$P$16716,1) -> 41 | H14: =SUMIFS(Data!$J$2:$J$16716,Data!$C$2:$C$16716,F14,Data!$P$2:$P$16716,1) -> 32.23 | P14: XB | Q14: =SUMIFS(Data!$J$2:$J$16716,Data!$B$2:$B$16716,P14,Data!$P$2:$P$16716,1) -> 258.26 | R14: =Q14+ROW()*0.000000001 -> 258.26 | X14: Square Enix | Y14: =SUMIFS(Data!$J$2:$J$16716,Data!$E$2:$E$16716,X14,Data!$P$2:$P$16716,1) -> 207.43 | Z14: =Y14+ROW()*0.000000001 -> 207.43
F15: 1992 | G15: =COUNTIFS(Data!$C$2:$C$16716,F15,Data!$P$2:$P$16716,1) -> 43 | H15: =SUMIFS(Data!$J$2:$J$16716,Data!$C$2:$C$16716,F15,Data!$P$2:$P$16716,1) -> 76.17 | P15: GB | Q15: =SUMIFS(Data!$J$2:$J$16716,Data!$B$2:$B$16716,P15,Data!$P$2:$P$16716,1) -> 255.45 | R15: =Q15+ROW()*0.000000001 -> 255.45 | X15: Capcom | Y15: =SUMIFS(Data!$J$2:$J$16716,Data!$E$2:$E$16716,X15,Data!$P$2:$P$16716,1) -> 200.02 | Z15: =Y15+ROW()*0.000000001 -> 200.02
F16: 1993 | G16: =COUNTIFS(Data!$C$2:$C$16716,F16,Data!$P$2:$P$16716,1) -> 60 | H16: =SUMIFS(Data!$J$2:$J$16716,Data!$C$2:$C$16716,F16,Data!$P$2:$P$16716,1) -> 45.98 | P16: NES | Q16: =SUMIFS(Data!$J$2:$J$16716,Data!$B$2:$B$16716,P16,Data!$P$2:$P$16716,1) -> 251.07 | R16: =Q16+ROW()*0.000000001 -> 251.07 | X16: Atari | Y16: =SUMIFS(Data!$J$2:$J$16716,Data!$E$2:$E$16716,X16,Data!$P$2:$P$16716,1) -> 156.83 | Z16: =Y16+ROW()*0.000000001 -> 156.83
F17: 1994 | G17: =COUNTIFS(Data!$C$2:$C$16716,F17,Data!$P$2:$P$16716,1) -> 121 | H17: =SUMIFS(Data!$J$2:$J$16716,Data!$C$2:$C$16716,F17,Data!$P$2:$P$16716,1) -> 79.18 | P17: N64 | Q17: =SUMIFS(Data!$J$2:$J$16716,Data!$B$2:$B$16716,P17,Data!$P$2:$P$16716,1) -> 218.88 | R17: =Q17+ROW()*0.000000001 -> 218.88 | X17: Warner Bros. Interactive Entertainment | Y17: =SUMIFS(Data!$J$2:$J$16716,Data!$E$2:$E$16716,X17,Data!$P$2:$P$16716,1) -> 151.79 | Z17: =Y17+ROW()*0.000000001 -> 151.79
F18: 1995 | G18: =COUNTIFS(Data!$C$2:$C$16716,F18,Data!$P$2:$P$16716,1) -> 219 | H18: =SUMIFS(Data!$J$2:$J$16716,Data!$C$2:$C$16716,F18,Data!$P$2:$P$16716,1) -> 88.11 | P18: SNES | Q18: =SUMIFS(Data!$J$2:$J$16716,Data!$B$2:$B$16716,P18,Data!$P$2:$P$16716,1) -> 200.05 | R18: =Q18+ROW()*0.000000001 -> 200.05 | X18: Disney Interactive Studios | Y18: =SUMIFS(Data!$J$2:$J$16716,Data!$E$2:$E$16716,X18,Data!$P$2:$P$16716,1) -> 117.37 | Z18: =Y18+ROW()*0.000000001 -> 117.37
F19: 1996 | G19: =COUNTIFS(Data!$C$2:$C$16716,F19,Data!$P$2:$P$16716,1) -> 263 | H19: =SUMIFS(Data!$J$2:$J$16716,Data!$C$2:$C$16716,F19,Data!$P$2:$P$16716,1) -> 199.15 | P19: GC | Q19: =SUMIFS(Data!$J$2:$J$16716,Data!$B$2:$B$16716,P19,Data!$P$2:$P$16716,1) -> 199.36 | R19: =Q19+ROW()*0.000000001 -> 199.36 | X19: Eidos Interactive | Y19: =SUMIFS(Data!$J$2:$J$16716,Data!$E$2:$E$16716,X19,Data!$P$2:$P$16716,1) -> 98.65 | Z19: =Y19+ROW()*0.000000001 -> 98.65
F20: 1997 | G20: =COUNTIFS(Data!$C$2:$C$16716,F20,Data!$P$2:$P$16716,1) -> 289 | H20: =SUMIFS(Data!$J$2:$J$16716,Data!$C$2:$C$16716,F20,Data!$P$2:$P$16716,1) -> 200.98 | P20: XOne | Q20: =SUMIFS(Data!$J$2:$J$16716,Data!$B$2:$B$16716,P20,Data!$P$2:$P$16716,1) -> 159.44 | R20: =Q20+ROW()*0.000000001 -> 159.44 | X20: LucasArts | Y20: =SUMIFS(Data!$J$2:$J$16716,Data!$E$2:$E$16716,X20,Data!$P$2:$P$16716,1) -> 85.83 | Z20: =Y20+ROW()*0.000000001 -> 85.83
F21: 1998 | G21: =COUNTIFS(Data!$C$2:$C$16716,F21,Data!$P$2:$P$16716,1) -> 379 | H21: =SUMIFS(Data!$J$2:$J$16716,Data!$C$2:$C$16716,F21,Data!$P$2:$P$16716,1) -> 256.45 | P21: 2600 | Q21: =SUMIFS(Data!$J$2:$J$16716,Data!$B$2:$B$16716,P21,Data!$P$2:$P$16716,1) -> 97.08 | R21: =Q21+ROW()*0.000000001 -> 97.08 | X21: Bethesda Softworks | Y21: =SUMIFS(Data!$J$2:$J$16716,Data!$E$2:$E$16716,X21,Data!$P$2:$P$16716,1) -> 85.05 | Z21: =Y21+ROW()*0.000000001 -> 85.05
F22: 1999 | G22: =COUNTIFS(Data!$C$2:$C$16716,F22,Data!$P$2:$P$16716,1) -> 338 | H22: =SUMIFS(Data!$J$2:$J$16716,Data!$C$2:$C$16716,F22,Data!$P$2:$P$16716,1) -> 251.25 | P22: WiiU | Q22: =SUMIFS(Data!$J$2:$J$16716,Data!$B$2:$B$16716,P22,Data!$P$2:$P$16716,1) -> 82.16 | R22: =Q22+ROW()*0.000000001 -> 82.16 | X22: Midway Games | Y22: =SUMIFS(Data!$J$2:$J$16716,Data!$E$2:$E$16716,X22,Data!$P$2:$P$16716,1) -> 69.67 | Z22: =Y22+ROW()*0.000000001 -> 69.67
F23: 2000 | G23: =COUNTIFS(Data!$C$2:$C$16716,F23,Data!$P$2:$P$16716,1) -> 350 | H23: =SUMIFS(Data!$J$2:$J$16716,Data!$C$2:$C$16716,F23,Data!$P$2:$P$16716,1) -> 201.58 | P23: PSV | Q23: =SUMIFS(Data!$J$2:$J$16716,Data!$B$2:$B$16716,P23,Data!$P$2:$P$16716,1) -> 54.12 | R23: =Q23+ROW()*0.000000001 -> 54.12 | X23: Acclaim Entertainment | Y23: =SUMIFS(Data!$J$2:$J$16716,Data!$E$2:$E$16716,X23,Data!$P$2:$P$16716,1) -> 64.15 | Z23: =Y23+ROW()*0.000000001 -> 64.15
F24: 2001 | G24: =COUNTIFS(Data!$C$2:$C$16716,F24,Data!$P$2:$P$16716,1) -> 482 | H24: =SUMIFS(Data!$J$2:$J$16716,Data!$C$2:$C$16716,F24,Data!$P$2:$P$16716,1) -> 331.47 | P24: SAT | Q24: =SUMIFS(Data!$J$2:$J$16716,Data!$B$2:$B$16716,P24,Data!$P$2:$P$16716,1) -> 33.59 | R24: =Q24+ROW()*0.000000001 -> 33.59 | X24: Vivendi Games | Y24: =SUMIFS(Data!$J$2:$J$16716,Data!$E$2:$E$16716,X24,Data!$P$2:$P$16716,1) -> 57.94 | Z24: =Y24+ROW()*0.000000001 -> 57.94
F25: 2002 | G25: =COUNTIFS(Data!$C$2:$C$16716,F25,Data!$P$2:$P$16716,1) -> 829 | H25: =SUMIFS(Data!$J$2:$J$16716,Data!$C$2:$C$16716,F25,Data!$P$2:$P$16716,1) -> 395.51 | P25: GEN | Q25: =SUMIFS(Data!$J$2:$J$16716,Data!$B$2:$B$16716,P25,Data!$P$2:$P$16716,1) -> 28.36 | R25: =Q25+ROW()*0.000000001 -> 28.36 | X25: 505 Games | Y25: =SUMIFS(Data!$J$2:$J$16716,Data!$E$2:$E$16716,X25,Data!$P$2:$P$16716,1) -> 55.32 | Z25: =Y25+ROW()*0.000000001 -> 55.32
F26: 2003 | G26: =COUNTIFS(Data!$C$2:$C$16716,F26,Data!$P$2:$P$16716,1) -> 775 | H26: =SUMIFS(Data!$J$2:$J$16716,Data!$C$2:$C$16716,F26,Data!$P$2:$P$16716,1) -> 357.8 | P26: DC | Q26: =SUMIFS(Data!$J$2:$J$16716,Data!$B$2:$B$16716,P26,Data!$P$2:$P$16716,1) -> 15.97 | R26: =Q26+ROW()*0.000000001 -> 15.97 | X26: Tecmo Koei | Y26: =SUMIFS(Data!$J$2:$J$16716,Data!$E$2:$E$16716,X26,Data!$P$2:$P$16716,1) -> 53.54 | Z26: =Y26+ROW()*0.000000001 -> 53.54
... F33: 2010 | G33: =COUNTIFS(Data!$C$2:$C$16716,F33,Data!$P$2:$P$16716,1) -> 1255 | H33: =SUMIFS(Data!$J$2:$J$16716,Data!$C$2:$C$16716,F33,Data!$P$2:$P$16716,1) -> 590.59 | P33: PCFX | Q33: =SUMIFS(Data!$J$2:$J$16716,Data!$B$2:$B$16716,P33,Data!$P$2:$P$16716,1) -> 0.03 | R33: =Q33+ROW()*0.000000001 -> 0.030000033 | X33: D3Publisher | Y33: =SUMIFS(Data!$J$2:$J$16716,Data!$E$2:$E$16716,X33,Data!$P$2:$P$16716,1) -> 23.74 | Z33: =Y33+ROW()*0.000000001 -> 23.74
F34: 2011 | G34: =COUNTIFS(Data!$C$2:$C$16716,F34,Data!$P$2:$P$16716,1) -> 1136 | H34: =SUMIFS(Data!$J$2:$J$16716,Data!$C$2:$C$16716,F34,Data!$P$2:$P$16716,1) -> 507.79 | X34: Hudson Soft | Y34: =SUMIFS(Data!$J$2:$J$16716,Data!$E$2:$E$16716,X34,Data!$P$2:$P$16716,1) -> 22.94 | Z34: =Y34+ROW()*0.000000001 -> 22.94
F35: 2012 | G35: =COUNTIFS(Data!$C$2:$C$16716,F35,Data!$P$2:$P$16716,1) -> 652 | H35: =SUMIFS(Data!$J$2:$J$16716,Data!$C$2:$C$16716,F35,Data!$P$2:$P$16716,1) -> 355.84 | X35: MTV Games | Y35: =SUMIFS(Data!$J$2:$J$16716,Data!$E$2:$E$16716,X35,Data!$P$2:$P$16716,1) -> 20.72 | Z35: =Y35+ROW()*0.000000001 -> 20.72
F36: 2013 | G36: =COUNTIFS(Data!$C$2:$C$16716,F36,Data!$P$2:$P$16716,1) -> 544 | H36: =SUMIFS(Data!$J$2:$J$16716,Data!$C$2:$C$16716,F36,Data!$P$2:$P$16716,1) -> 361.24 | X36: Universal Interactive | Y36: =SUMIFS(Data!$J$2:$J$16716,Data!$E$2:$E$16716,X36,Data!$P$2:$P$16716,1) -> 17.77 | Z36: =Y36+ROW()*0.000000001 -> 17.77
F37: 2014 | G37: =COUNTIFS(Data!$C$2:$C$16716,F37,Data!$P$2:$P$16716,1) -> 581 | H37: =SUMIFS(Data!$J$2:$J$16716,Data!$C$2:$C$16716,F37,Data!$P$2:$P$16716,1) -> 331.51 | X37: Banpresto | Y37: =SUMIFS(Data!$J$2:$J$16716,Data!$E$2:$E$16716,X37,Data!$P$2:$P$16716,1) -> 17.4 | Z37: =Y37+ROW()*0.000000001 -> 17.4
F38: 2015 | G38: =COUNTIFS(Data!$C$2:$C$16716,F38,Data!$P$2:$P$16716,1) -> 606 | H38: =SUMIFS(Data!$J$2:$J$16716,Data!$C$2:$C$16716,F38,Data!$P$2:$P$16716,1) -> 268.05 | X38: Rising Star Games | Y38: =SUMIFS(Data!$J$2:$J$16716,Data!$E$2:$E$16716,X38,Data!$P$2:$P$16716,1) -> 16.82 | Z38: =Y38+ROW()*0.000000001 -> 16.82
F39: 2016 | G39: =COUNTIFS(Data!$C$2:$C$16716,F39,Data!$P$2:$P$16716,1) -> 502 | H39: =SUMIFS(Data!$J$2:$J$16716,Data!$C$2:$C$16716,F39,Data!$P$2:$P$16716,1) -> 130.1 | X39: Infogrames | Y39: =SUMIFS(Data!$J$2:$J$16716,Data!$E$2:$E$16716,X39,Data!$P$2:$P$16716,1) -> 16.34 | Z39: =Y39+ROW()*0.000000001 -> 16.34
X40: Majesco Entertainment | Y40: =SUMIFS(Data!$J$2:$J$16716,Data!$E$2:$E$16716,X40,Data!$P$2:$P$16716,1) -> 15.79 | Z40: =Y40+ROW()*0.000000001 -> 15.79
X41: Hasbro Interactive | Y41: =SUMIFS(Data!$J$2:$J$16716,Data!$E$2:$E$16716,X41,Data!$P$2:$P$16716,1) -> 15.22 | Z41: =Y41+ROW()*0.000000001 -> 15.22
X42: Nippon Ichi Software | Y42: =SUMIFS(Data!$J$2:$J$16716,Data!$E$2:$E$16716,X42,Data!$P$2:$P$16716,1) -> 13.66 | Z42: =Y42+ROW()*0.000000001 -> 13.66
X43: 989 Studios | Y43: =SUMIFS(Data!$J$2:$J$16716,Data!$E$2:$E$16716,X43,Data!$P$2:$P$16716,1) -> 13.32 | Z43: =Y43+ROW()*0.000000001 -> 13.32
X44: Zoo Digital Publishing | Y44: =SUMIFS(Data!$J$2:$J$16716,Data!$E$2:$E$16716,X44,Data!$P$2:$P$16716,1) -> 12.81 | Z44: =Y44+ROW()*0.000000001 -> 12.81
X45: Atlus | Y45: =SUMIFS(Data!$J$2:$J$16716,Data!$E$2:$E$16716,X45,Data!$P$2:$P$16716,1) -> 12.36 | Z45: =Y45+ROW()*0.000000001 -> 12.36
X46: Level 5 | Y46: =SUMIFS(Data!$J$2:$J$16716,Data!$E$2:$E$16716,X46,Data!$P$2:$P$16716,1) -> 12.24 | Z46: =Y46+ROW()*0.000000001 -> 12.24
...

Sheet Lists
A1: Genre | B1: Platform Maker | C1: Year
A2: All | B2: All | C2: 1980
A3: Action | B3: Sony | C3: 1981
A4: Sports | B4: Nintendo | C4: 1982
A5: Shooter | B5: Microsoft | C5: 1983
A6: Role-Playing | B6: Sega | C6: 1984
A7: Platform | B7: PC | C7: 1985
A8: Misc | B8: Other | C8: 1986
A9: Racing | C9: 1987
A10: Fighting | C10: 1988
A11: Simulation | C11: 1989
A12: Puzzle | C12: 1990
A13: Adventure | C13: 1991
A14: Strategy | C14: 1992
C15: 1993
C16: 1994
C17: 1995
C18: 1996
C19: 1997
C20: 1998
C21: 1999
C22: 2000
C23: 2001
C24: 2002
C25: 2003
C26: 2004
... C38: 2016

Sheet Insights
B1: Key insights & recommendations (full dataset, no filters)
B3: Market size | C3: 16,715 cleaned release records, 8.92B units sold (1980-2016). Peak year 2008 (672M units).
B4: Hit-driven market | C4: Top 1% of releases = 21% of units; top 10% = 59%; 35% of releases sold under 100k units.
B5: Genres | C5: Action (19.6%), Sports (14.9%), Shooter (11.8%) lead in volume. Platform (0.93M), Shooter (0.80M), RPG (0.62M) earn most per release; Adventure only 0.18M.
B6: Platforms | C6: PS2 #1 (1,256M), then X360, PS3, Wii. Sony 3.59B and Nintendo 3.50B vs Microsoft 1.39B. Each platform has a ~5-8 year sales window.
B7: Publishers | C7: Top 10 hold ~71% of units. Nintendo #1 (1.79B) with 2.5M units per release vs 0.7-0.9M for EA / Activision / Sony.
B8: Best sellers | C8: Wii Sports 82.5M. Combined across platforms GTA V (56.6M) is #2.
B9: Regions | C9: North America 49.4%, Europe 27.2%, Japan 14.6%, Other 8.9%. RPG = 38% Japan; Shooters only 4% Japan.
B10: Ratings vs sales | C10: Critic score vs sales Spearman rho 0.38 (user score 0.16). 90+ rated games average 3.2M units - ~14x games under 50.
B11: Recommend: portfolio | C11: Concentrate on Action / Shooter / RPG / Platform franchises; limit spend on Adventure / Strategy / Puzzle.
B12: Recommend: quality | C12: Invest in QA and polish to reach 80+ critic scores - the largest sales step-up of any factor tested.
B13: Recommend: platforms | C13: Launch early/mid-lifecycle on current-gen platforms and go multi-platform.
B14: Recommend: regions | C14: Lead with NA/EU for shooters, sports, racing; build a Japan-specific plan for RPG and puzzle/strategy.
B15: Limitations | C15: 2016 snapshot, mostly physical retail; no revenue/cost data; ~50% of games unscored; correlation is not causation.

Sheet Cleaning_Log
A1: Step | B1: Rows affected | C1: Note
A2: Raw rows loaded | B2: 16719
A3: Name values with stray whitespace trimmed | B3: 29 | C3: e.g. trailing spaces in Name / Publisher
A4: Rows dropped: missing Name AND Genre | B4: 2 | C4: Both are Genesis 1993 rows, cannot be identified
A5: Invalid Year set to NaN (>2016) | B5: 4 | C5: Impossible for a Dec-2016 snapshot (2017 / 2020 values)
A6: Duplicate Name+Platform rows merged (sales summed) | B6: 2 | C6: 2 games; kept distinct releases with different years
A7: Missing Publisher -> "Unknown" | B7: 53
A8: Missing Developer -> "Unknown" | B8: 6621
A9: Publisher variants consolidated | B9: 9 | C9: Square/SquareSoft->Square Enix, Sony CE America/Europe->Sony CE, etc.
A10: Rating: K-A merged into E; RP set to NaN | B10: 6
A11: Score columns left missing (NOT imputed) | B11: 8580 | C11: Imputing would invent ratings; score analysis uses only rated games
A12: Rows where regions != Global by >0.05M | B12: 0 | C12: Differences <=0.02M are rounding; Global kept as reported
A13: Final rows | B13: 16715 | C13: 4 rows removed in total
